ERROR:django.request:Internal Server Error: /login/
Traceback (most recent call last):
  File "/home/ucat/Temp/devsecops_sample/venv/lib/python3.12/site-packages/django/db/backends/utils.py", line 89, in _execute
    return self.cursor.execute(sql, params)
           ^^^^^^^^^^^^^^^^^^^^^^^^^^^^^^^^
  File "/home/ucat/Temp/devsecops_sample/venv/lib/python3.12/site-packages/django/db/backends/sqlite3/base.py", line 357, in execute
    return Database.Cursor.execute(self, query, params)
           ^^^^^^^^^^^^^^^^^^^^^^^^^^^^^^^^^^^^^^^^^^^^
sqlite3.OperationalError: no such table: django_site

The above exception was the direct cause of the following exception:

Traceback (most recent call last):
  File "/home/ucat/Temp/devsecops_sample/venv/lib/python3.12/site-packages/django/core/handlers/exception.py", line 56, in inner
    response = get_response(request)
               ^^^^^^^^^^^^^^^^^^^^^
  File "/home/ucat/Temp/devsecops_sample/venv/lib/python3.12/site-packages/django/core/handlers/base.py", line 197, in _get_response
    response = wrapped_callback(request, *callback_args, **callback_kwargs)
               ^^^^^^^^^^^^^^^^^^^^^^^^^^^^^^^^^^^^^^^^^^^^^^^^^^^^^^^^^^^^
  File "/home/ucat/Temp/devsecops_sample/venv/lib/python3.12/site-packages/django/views/generic/base.py", line 103, in view
    return self.dispatch(request, *args, **kwargs)
           ^^^^^^^^^^^^^^^^^^^^^^^^^^^^^^^^^^^^^^^
  File "/home/ucat/Temp/devsecops_sample/venv/lib/python3.12/site-packages/django/utils/decorators.py", line 46, in _wrapper
    return bound_method(*args, **kwargs)
           ^^^^^^^^^^^^^^^^^^^^^^^^^^^^^
  File "/home/ucat/Temp/devsecops_sample/venv/lib/python3.12/site-packages/django/views/decorators/debug.py", line 92, in sensitive_post_parameters_wrapper
    return view(request, *args, **kwargs)
           ^^^^^^^^^^^^^^^^^^^^^^^^^^^^^^
  File "/home/ucat/Temp/devsecops_sample/venv/lib/python3.12/site-packages/django/utils/decorators.py", line 46, in _wrapper
    return bound_method(*args, **kwargs)
           ^^^^^^^^^^^^^^^^^^^^^^^^^^^^^
  File "/home/ucat/Temp/devsecops_sample/venv/lib/python3.12/site-packages/django/utils/decorators.py", line 134, in _wrapped_view
    response = view_func(request, *args, **kwargs)
               ^^^^^^^^^^^^^^^^^^^^^^^^^^^^^^^^^^^
  File "/home/ucat/Temp/devsecops_sample/venv/lib/python3.12/site-packages/django/utils/decorators.py", line 46, in _wrapper
    return bound_method(*args, **kwargs)
           ^^^^^^^^^^^^^^^^^^^^^^^^^^^^^
  File "/home/ucat/Temp/devsecops_sample/venv/lib/python3.12/site-packages/django/views/decorators/cache.py", line 62, in _wrapped_view_func
    response = view_func(request, *args, **kwargs)
               ^^^^^^^^^^^^^^^^^^^^^^^^^^^^^^^^^^^
  File "/home/ucat/Temp/devsecops_sample/venv/lib/python3.12/site-packages/django/contrib/auth/views.py", line 90, in dispatch
    return super().dispatch(request, *args, **kwargs)
           ^^^^^^^^^^^^^^^^^^^^^^^^^^^^^^^^^^^^^^^^^^
  File "/home/ucat/Temp/devsecops_sample/venv/lib/python3.12/site-packages/django/views/generic/base.py", line 142, in dispatch
    return handler(request, *args, **kwargs)
           ^^^^^^^^^^^^^^^^^^^^^^^^^^^^^^^^^
  File "/home/ucat/Temp/devsecops_sample/venv/lib/python3.12/site-packages/django/views/generic/edit.py", line 144, in get
    return self.render_to_response(self.get_context_data())
                                   ^^^^^^^^^^^^^^^^^^^^^^^
  File "/home/ucat/Temp/devsecops_sample/venv/lib/python3.12/site-packages/django/contrib/auth/views.py", line 114, in get_context_data
    current_site = get_current_site(self.request)
                   ^^^^^^^^^^^^^^^^^^^^^^^^^^^^^^
  File "/home/ucat/Temp/devsecops_sample/venv/lib/python3.12/site-packages/django/contrib/sites/shortcuts.py", line 16, in get_current_site
    return Site.objects.get_current(request)
           ^^^^^^^^^^^^^^^^^^^^^^^^^^^^^^^^^
  File "/home/ucat/Temp/devsecops_sample/venv/lib/python3.12/site-packages/django/contrib/sites/models.py", line 59, in get_current
    return self._get_site_by_id(site_id)
           ^^^^^^^^^^^^^^^^^^^^^^^^^^^^^
  File "/home/ucat/Temp/devsecops_sample/venv/lib/python3.12/site-packages/django/contrib/sites/models.py", line 30, in _get_site_by_id
    site = self.get(pk=site_id)
           ^^^^^^^^^^^^^^^^^^^^
  File "/home/ucat/Temp/devsecops_sample/venv/lib/python3.12/site-packages/django/db/models/manager.py", line 85, in manager_method
    return getattr(self.get_queryset(), name)(*args, **kwargs)
           ^^^^^^^^^^^^^^^^^^^^^^^^^^^^^^^^^^^^^^^^^^^^^^^^^^^
  File "/home/ucat/Temp/devsecops_sample/venv/lib/python3.12/site-packages/django/db/models/query.py", line 646, in get
    num = len(clone)
          ^^^^^^^^^^
  File "/home/ucat/Temp/devsecops_sample/venv/lib/python3.12/site-packages/django/db/models/query.py", line 376, in __len__
    self._fetch_all()
  File "/home/ucat/Temp/devsecops_sample/venv/lib/python3.12/site-packages/django/db/models/query.py", line 1867, in _fetch_all
    self._result_cache = list(self._iterable_class(self))
                         ^^^^^^^^^^^^^^^^^^^^^^^^^^^^^^^^
  File "/home/ucat/Temp/devsecops_sample/venv/lib/python3.12/site-packages/django/db/models/query.py", line 87, in __iter__
    results = compiler.execute_sql(
              ^^^^^^^^^^^^^^^^^^^^^
  File "/home/ucat/Temp/devsecops_sample/venv/lib/python3.12/site-packages/django/db/models/sql/compiler.py", line 1398, in execute_sql
    cursor.execute(sql, params)
  File "/home/ucat/Temp/devsecops_sample/venv/lib/python3.12/site-packages/django/db/backends/utils.py", line 102, in execute
    return super().execute(sql, params)
           ^^^^^^^^^^^^^^^^^^^^^^^^^^^^
  File "/home/ucat/Temp/devsecops_sample/venv/lib/python3.12/site-packages/django/db/backends/utils.py", line 67, in execute
    return self._execute_with_wrappers(
           ^^^^^^^^^^^^^^^^^^^^^^^^^^^^
  File "/home/ucat/Temp/devsecops_sample/venv/lib/python3.12/site-packages/django/db/backends/utils.py", line 80, in _execute_with_wrappers
    return executor(sql, params, many, context)
           ^^^^^^^^^^^^^^^^^^^^^^^^^^^^^^^^^^^^
  File "/home/ucat/Temp/devsecops_sample/venv/lib/python3.12/site-packages/django/db/backends/utils.py", line 84, in _execute
    with self.db.wrap_database_errors:
         ^^^^^^^^^^^^^^^^^^^^^^^^^^^^
  File "/home/ucat/Temp/devsecops_sample/venv/lib/python3.12/site-packages/django/db/utils.py", line 91, in __exit__
    raise dj_exc_value.with_traceback(traceback) from exc_value
  File "/home/ucat/Temp/devsecops_sample/venv/lib/python3.12/site-packages/django/db/backends/utils.py", line 89, in _execute
    return self.cursor.execute(sql, params)
           ^^^^^^^^^^^^^^^^^^^^^^^^^^^^^^^^
  File "/home/ucat/Temp/devsecops_sample/venv/lib/python3.12/site-packages/django/db/backends/sqlite3/base.py", line 357, in execute
    return Database.Cursor.execute(self, query, params)
           ^^^^^^^^^^^^^^^^^^^^^^^^^^^^^^^^^^^^^^^^^^^^
django.db.utils.OperationalError: no such table: django_site
WARNING:django.request:Not Found: /favicon.ico
